ArgumentError: Argument 'sqlite_on_conflict' is not accepted by dialect 'sqlite' on behalf of <class 'sqlalchemy.sql.schema.Table'>
Traceback:
File "/home/runner/TradeAI-financequant/.pythonlibs/lib/python3.11/site-packages/streamlit/runtime/scriptrunner/exec_code.py", line 88, in exec_func_with_error_handling
    result = func()
             ^^^^^^
File "/home/runner/TradeAI-financequant/.pythonlibs/lib/python3.11/site-packages/streamlit/runtime/scriptrunner/script_runner.py", line 579, in code_to_exec
    exec(code, module.__dict__)
File "/home/runner/TradeAI-financequant/main.py", line 8, in <module>
    from data_handler import DataHandler
File "/home/runner/TradeAI-financequant/data_handler.py", line 6, in <module>
    from models import Session, StockData
File "/home/runner/TradeAI-financequant/models.py", line 8, in <module>
    class StockData(Base):
File "/home/runner/TradeAI-financequant/.pythonlibs/lib/python3.11/site-packages/sqlalchemy/orm/decl_api.py", line 196, in __init__
    _as_declarative(reg, cls, dict_)
File "/home/runner/TradeAI-financequant/.pythonlibs/lib/python3.11/site-packages/sqlalchemy/orm/decl_base.py", line 244, in _as_declarative
    return _MapperConfig.setup_mapping(registry, cls, dict_, None, {})
           ^^^^^^^^^^^^^^^^^^^^^^^^^^^^^^^^^^^^^^^^^^^^^^^^^^^^^^^^^^^
File "/home/runner/TradeAI-financequant/.pythonlibs/lib/python3.11/site-packages/sqlalchemy/orm/decl_base.py", line 325, in setup_mapping
    return _ClassScanMapperConfig(
           ^^^^^^^^^^^^^^^^^^^^^^^
File "/home/runner/TradeAI-financequant/.pythonlibs/lib/python3.11/site-packages/sqlalchemy/orm/decl_base.py", line 576, in __init__
    self._setup_table(table)
File "/home/runner/TradeAI-financequant/.pythonlibs/lib/python3.11/site-packages/sqlalchemy/orm/decl_base.py", line 1759, in _setup_table
    table_cls(
File "<string>", line 2, in __new__
File "/home/runner/TradeAI-financequant/.pythonlibs/lib/python3.11/site-packages/sqlalchemy/util/deprecations.py", line 281, in warned
    return fn(*args, **kwargs)  # type: ignore[no-any-return]
           ^^^^^^^^^^^^^^^^^^^
File "/home/runner/TradeAI-financequant/.pythonlibs/lib/python3.11/site-packages/sqlalchemy/sql/schema.py", line 427, in __new__
    return cls._new(*args, **kw)
           ^^^^^^^^^^^^^^^^^^^^^
File "/home/runner/TradeAI-financequant/.pythonlibs/lib/python3.11/site-packages/sqlalchemy/sql/schema.py", line 481, in _new
    with util.safe_reraise():
File "/home/runner/TradeAI-financequant/.pythonlibs/lib/python3.11/site-packages/sqlalchemy/util/langhelpers.py", line 146, in __exit__
    raise exc_value.with_traceback(exc_tb)
File "/home/runner/TradeAI-financequant/.pythonlibs/lib/python3.11/site-packages/sqlalchemy/sql/schema.py", line 477, in _new
    table.__init__(name, metadata, *args, _no_init=False, **kw)
File "/home/runner/TradeAI-financequant/.pythonlibs/lib/python3.11/site-packages/sqlalchemy/sql/schema.py", line 851, in __init__
    self._extra_kwargs(**kw)
File "/home/runner/TradeAI-financequant/.pythonlibs/lib/python3.11/site-packages/sqlalchemy/sql/schema.py", line 999, in _extra_kwargs
    self._validate_dialect_kwargs(kwargs)
File "/home/runner/TradeAI-financequant/.pythonlibs/lib/python3.11/site-packages/sqlalchemy/sql/base.py", line 617, in _validate_dialect_kwargs
    raise exc.ArgumentError(